<?xml version="1.0" ?>
<!-- =================================================================================== -->
<!-- |    This document was autogenerated by xacro from src/joint_controller/urdf/two_link_linkage.urdf.xacro | -->
<!-- |    EDITING THIS FILE BY HAND IS NOT RECOMMENDED                                 | -->
<!-- =================================================================================== -->
<!--two_link_linkage.urdf.xacro -->
<robot name="two_link_linkage">
  <!-- Fixed to the world -->
  <link name="world"/>
  <!-- Define a joint between world and base_link -->
  <joint name="/fixed" type="fixed">
    <parent link="world"/>
    <child link="/base_link"/>
  </joint>
  <!-- 固定的link -->
  <link name="/base_link">
    <visual>
      <geometry>
        <!-- 长方体的长宽高 -->
        <!-- <box size="0.5 0.3 0.1" />-->
        <!-- 圆柱的半径和长度 -->
        <!-- <cylinder radius="0.5" length="0.1" /> -->
        <!-- 球体的半径-->
        <box size="0.1 0.1 0.8"/>
      </geometry>
      <!-- 位置：x y z 轴位置 roll pitch yaw 旋转 -->
      <origin rpy="0.0 0.0 0.0" xyz="0.0 0.0 0.4"/>
      <!-- rgba颜色 -->
      <material name="black">
        <color rgba="0.7 0.5 0 0.5"/>
      </material>
    </visual>
    <collision>
      <origin rpy="0 0 0" xyz="0.0 0.0 0.4"/>
      <geometry>
        <box size="0.1 0.1 0.8"/>
      </geometry>
    </collision>
    <!-- 惯量矩阵 -->
    <inertial>
      <origin rpy="0 0 0" xyz="0.0 0.0 0.4"/>
      <mass value="0.5"/>
      <inertia ixx="0.027083333" ixy="0.0" ixz="0.0" iyy="0.027083333" iyz="0.0" izz="0.000833333"/>
    </inertial>
  </link>
  <!-- 二连杆的关节 -->
  <joint name="/joint1" type="revolute">
    <axis xyz="0 1 0"/>
    <!-- 定义旋转轴为 y轴 -->
    <!-- 常见设置包括：
            xyz="1 0 0" 表示关节绕x轴旋转
            xyz="0 1 0" 表示关节绕y轴旋转
            xyz="0 0 1" 表示关节绕z轴旋转
        -->
    <origin rpy="0 1.57 0" xyz="0 0.1 0.75"/>
    <!--      limit not work while type="continuous"-->
    <limit effort="5." lower="-3.14" upper="3.14" velocity="50."/>
    <dynamics damping="0.01" friction="0.02"/>
    <parent link="/base_link"/>
    <child link="/rotating_link"/>
  </joint>
  <!-- 旋转link -->
  <link name="/rotating_link">
    <visual>
      <geometry>
        <box size="0.1 0.1 0.3"/>
      </geometry>
      <!-- 位置：x y z 轴位置 roll pitch yaw 旋转 -->
      <origin rpy="0.0 0.0 0.0" xyz="0.0 0.1 0.1"/>
      <material name="black">
        <color rgba="0.7 0.5 0 0.5"/>
      </material>
    </visual>
    <collision>
      <origin rpy="0 0 0" xyz="0.0 0.1 0.1"/>
      <geometry>
        <box size="0.1 0.1 0.3"/>
      </geometry>
    </collision>
    <!-- 惯量矩阵 -->
    <inertial>
      <origin rpy="0 0 0" xyz="0.0 0.1 0.1"/>
      <mass value="0.5"/>
      <inertia ixx="0.004166667" ixy="0.0" ixz="0.0" iyy="0.004166667" iyz="0.0" izz="0.000833333"/>
    </inertial>
  </link>
  <transmission name="/joint1_tran">
    <type>transmission_interface/SimpleTransmission</type>
    <joint name="/joint1">
      <hardwareInterface>hardware_interface/EffortJointInterface</hardwareInterface>
    </joint>
    <actuator name="/joint1_motor">
      <hardwareInterface>hardware_interface/EffortJointInterface</hardwareInterface>
      <mechanicalReduction>19.2032</mechanicalReduction>
    </actuator>
  </transmission>
  <!-- plugin the gazebo_ros_control pluginlib -->
  <gazebo>
    <plugin filename="libgazebo_ros_control.so" name="gazebo_ros_control">
      <robotNamespace></robotNamespace>
    </plugin>
  </gazebo>
</robot>
